<mujoco model="pusher_plane_2d">
    <compiler angle="radian" inertiafromgeom="true"/>
    <default>
        <joint armature="1" damping="1" limited="true"/>
        <geom contype="0" friction="1. 0.1 0.1" rgba="0.7 0.7 0 1" solimp=".5 .5 .001" solref=".02 1"/>
    </default>
    <option integrator="RK4" timestep="0.01"/>
    <worldbody>
        <!-- Ground -->
        <geom conaffinity="1" contype="1" name="ground" pos="0 0 0" rgba="0.9 0.9 0.9 1" size="1 1 10" type="plane" condim="3"/>
        <!-- Ground Center -->
        <body name="center" pos="0. 0. 0.">
            <geom conaffinity="0" contype="0" name="center" pos="0 0 0" rgba="0. 0. 1.0 1" size=".009" type="sphere"/>
        </body>
        <!-- Pusher -->
        <body name="pusher" pos="0.5 0 .055">
            <geom rgba="1 0.5 0 1" type="box" size="0.01 0.05 0.05" density='1.0' contype="1" conaffinity="1" condim="3" friction="0.01 0.01 0.01"/>
            <joint name="push_slidex" type="slide" pos="0 0 0" axis="1 0 0" range="-10.3213 10.3" damping="0."/> 
            <joint name="push_slidey" type="slide" pos="0 0 0" axis="0 1 0" range="-10.3213 10.3" damping="0."/> 
            <joint name="push_hinge" type="hinge" pos="0 0 0" axis="0 0 1" range="-1000. 1000.0" damping="0."/>
        </body>
        <!-- Object -->
        <body name="object" pos="0. 0. 0." >
            <geom rgba="0 1 1 1" type="cylinder" size="0.025 0.015 0.05" contype="1" friction="0.5 0.1 0.1" conaffinity="1"/>
            <joint name="object_slidex" type="slide" pos="0 0 0" axis="1 0 0" range="-10.3213 10.3" damping="1."/> 
            <joint name="object_slidey" type="slide" pos="0 0 0" axis="0 1 0" range="-10.3213 10.3" damping="1."/>
            <joint name="object_slidez" type="slide" pos="0 0 0" axis="0 0 1" range="-10.3213 10.3" damping="0.5"/>
        </body>
        <!-- Object Goal -->
        <body name="goal" pos="0. 0. 0.01">
            <geom rgba="0 1 0 1" type="cylinder" size="0.025 0.005 0.05" contype="0" conaffinity="0"/>
            <joint name="goal_slidex" type="slide" pos="0 0 0" axis="1 0 0" range="-10.3213 10.3" damping="0."/> 
            <joint name="goal_slidey" type="slide" pos="0 0 0" axis="0 1 0" range="-10.3213 10.3" damping="0."/>
        </body>
        <camera euler="0 0 0" fovy="50" name="top_cam" pos="0 0 1.0"></camera>

    </worldbody>
    <actuator>
        <motor ctrllimited="true" ctrlrange="-1.0 1.0" gear="2000.0" joint="push_slidex"/>
        <motor ctrllimited="true" ctrlrange="-1.0 1.0" gear="2000.0" joint="push_slidey"/>
        <motor ctrllimited="true" ctrlrange="-1.0 1.0" gear="2000.0" joint="push_hinge"/>
    </actuator>
</mujoco> 

